<?xml version="1.0" ?>
<!-- =================================================================================== -->
<!-- |    This document was autogenerated by xacro from sonny_main.urdf.xacro          | -->
<!-- |    EDITING THIS FILE BY HAND IS NOT RECOMMENDED                                 | -->
<!-- =================================================================================== -->
<robot name="sonny_main">
  <!-- *************** MACROS AND PROPERTIES ****************  -->
  <!-- *************** LINKS AND JOINTS **************** -->
  <!-- Robot Base -->
  <link name="base_link">
    <visual>
      <geometry>
        <box size="0.62 0.51 0.18"/>
      </geometry>
      <material name="Grey">
        <color rgba="0.2 0.2 0.2 1"/>
      </material>
    </visual>
    <collision>
      <geometry>
        <box size="0.62 0.51 0.18"/>
      </geometry>
    </collision>
  </link>
  <!-- Robot Footprint -->
  <link name="base_footprint">
    <inertial>
      <origin rpy="1.5707963267948966 0 1.5707963267948966" xyz="0 0 0"/>
      <mass value="15"/>
      <inertia ixx="0.521" ixy="0.0" ixz="0.0" iyy="0.805625" iyz="0.0" izz="0.365625"/>
    </inertial>
  </link>
  <joint name="base_joint" type="fixed">
    <parent link="base_link"/>
    <child link="base_footprint"/>
    <origin rpy="0 0 0" xyz="0.0 0.0 -0.15000000000000002"/>
  </joint>
  <link name="drivewhl_l_link">
    <visual>
      <origin rpy="1.5707963267948966 0 0" xyz="0 0 0"/>
      <geometry>
        <cylinder length="0.04" radius="0.1"/>
      </geometry>
      <material name="Gray">
        <color rgba="0.5 0.5 0.5 1.0"/>
      </material>
    </visual>
    <collision>
      <origin rpy="1.5707963267948966 0 0" xyz="0 0 0"/>
      <geometry>
        <cylinder length="0.04" radius="0.1"/>
      </geometry>
    </collision>
    <inertial>
      <origin rpy="1.5707963267948966 0 0" xyz="0 0 0"/>
      <mass value="0.5"/>
      <inertia ixx="0.0013166666666666667" ixy="0" ixz="0" iyy="0.0013166666666666667" iyz="0" izz="0.0025000000000000005"/>
    </inertial>
  </link>
  <joint name="drivewhl_l_joint" type="continuous">
    <parent link="base_link"/>
    <child link="drivewhl_l_link"/>
    <origin rpy="0 0 0" xyz="-0.12 0.28 -0.05"/>
    <axis xyz="0 1 0"/>
  </joint>
  <link name="drivewhl_r_link">
    <visual>
      <origin rpy="1.5707963267948966 0 0" xyz="0 0 0"/>
      <geometry>
        <cylinder length="0.04" radius="0.1"/>
      </geometry>
      <material name="Gray">
        <color rgba="0.5 0.5 0.5 1.0"/>
      </material>
    </visual>
    <collision>
      <origin rpy="1.5707963267948966 0 0" xyz="0 0 0"/>
      <geometry>
        <cylinder length="0.04" radius="0.1"/>
      </geometry>
    </collision>
    <inertial>
      <origin rpy="1.5707963267948966 0 0" xyz="0 0 0"/>
      <mass value="0.5"/>
      <inertia ixx="0.0013166666666666667" ixy="0" ixz="0" iyy="0.0013166666666666667" iyz="0" izz="0.0025000000000000005"/>
    </inertial>
  </link>
  <joint name="drivewhl_r_joint" type="continuous">
    <parent link="base_link"/>
    <child link="drivewhl_r_link"/>
    <origin rpy="0 0 0" xyz="-0.12 -0.28 -0.05"/>
    <axis xyz="0 1 0"/>
  </joint>
  <!-- Caster Wheel -->
  <link name="front_caster">
    <visual>
      <geometry>
        <sphere radius="0.060000000000000026"/>
      </geometry>
      <material name="Cyan">
        <color rgba="0 1.0 1.0 1.0"/>
      </material>
    </visual>
    <collision>
      <origin rpy="0 0 0" xyz="0 0 0"/>
      <geometry>
        <sphere radius="0.060000000000000026"/>
      </geometry>
    </collision>
    <inertial>
      <mass value="0.5"/>
      <inertia ixx="0.0007200000000000006" ixy="0.0" ixz="0.0" iyy="0.0007200000000000006" iyz="0.0" izz="0.0007200000000000006"/>
    </inertial>
  </link>
  <joint name="caster_joint" type="fixed">
    <parent link="base_link"/>
    <child link="front_caster"/>
    <origin rpy="0 0 0" xyz="0.14 0.0 -0.09"/>
  </joint>
  <link name="imu_link">
    <visual name="imu_link_visual">
      <geometry>
        <box size="0.1 0.1 0.1"/>
      </geometry>
    </visual>
    <collision name="imu_link_collision">
      <geometry>
        <box size="0.1 0.1 0.1"/>
      </geometry>
    </collision>
    <inertial>
      <origin rpy="1.5707963267948966 0 1.5707963267948966" xyz="0 0 0"/>
      <mass value="0.1"/>
      <inertia ixx="0.0001666666666666667" ixy="0.0" ixz="0.0" iyy="0.0001666666666666667" iyz="0.0" izz="0.0001666666666666667"/>
    </inertial>
  </link>
  <joint name="imu_joint" type="fixed">
    <parent link="base_link"/>
    <child link="imu_link"/>
    <origin rpy="0 0 0" xyz="0.0 0.0 0.01"/>
  </joint>
  <link name="lidar_link">
    <visual name="lidar_link_visual">
      <geometry>
        <cylinder length="0.055" radius="0.0508"/>
      </geometry>
    </visual>
    <collision name="lidar_link_collision">
      <geometry>
        <cylinder length="0.055" radius="0.0508"/>
      </geometry>
    </collision>
    <inertial>
      <origin rpy="1.5707963267948966 0 0" xyz="0 0 0"/>
      <mass value="0.125"/>
      <inertia ixx="0.00011215541666666665" ixy="0" ixz="0" iyy="0.00011215541666666665" iyz="0" izz="0.00016129"/>
    </inertial>
  </link>
  <joint name="lidar_joint" type="fixed">
    <parent link="base_link"/>
    <child link="lidar_link"/>
    <origin rpy="0 0 0" xyz="0.14 0.0 0.12"/>
  </joint>
  <gazebo reference="drivewhl_l_link">
    <mu1 value="1.0"/>
    <mu2 value="1.0"/>
  </gazebo>
  <gazebo reference="drivewhl_r_link">
    <mu1 value="1.0"/>
    <mu2 value="1.0"/>
  </gazebo>
  <gazebo reference="front_caster">
    <mu1 value="0.1"/>
    <mu2 value="0.1"/>
  </gazebo>
  <!-- Gazebo Plugins -->
  <gazebo>
    <plugin filename="gz-sim-diff-drive-system" name="gz::sim::systems::DiffDrive">
      <!-- <odom_publisher_frequency>50</odom_publisher_frequency> -->
      <left_joint>drivewhl_l_joint</left_joint>
      <right_joint>drivewhl_r_joint</right_joint>
      <!-- kinematics -->
      <wheel_separation>0.4</wheel_separation>
      <wheel_radius>0.1</wheel_radius>
      <!-- limits -->
      <!-- <max_wheel_torque>20</max_wheel_torque> -->
      <max_linear_acceleration>0.5</max_linear_acceleration>
      <!-- input -->
      <topic>/demo/cmd_vel</topic>
      <publish_odom>true</publish_odom>
      <publish_odom_tf>true</publish_odom_tf>
      <publish_wheel_tf>true</publish_wheel_tf>
      <!-- output -->
      <odom_topic>/demo/odom</odom_topic>
      <frame_id>odom</frame_id>
      <child_frame_id>base_link</child_frame_id>
      <tf_topic>/tf</tf_topic>
    </plugin>
    <plugin filename="gz-sim-joint-state-publisher-system" name="gz::sim::systems::JointStatePublisher">
      <topic>joint_states</topic>
      <!-- <update_rate>50</update_rate>
      <joint_name>left_wheel_joint</joint_name>
      <joint_name>right_wheel_joint</joint_name> -->
    </plugin>
  </gazebo>
  <!-- Lidar Plugin -->
  <gazebo reference="lidar_link">
    <sensor name="lidar" type="gpu_lidar">
      <!-- <pose>0 0 0 0 0 0</pose> -->
      <always_on>true</always_on>
      <visualize>true</visualize>
      <update_rate>5</update_rate>
      <lidar>
        <scan>
          <horizontal>
            <samples>360</samples>
            <resolution>1.000000</resolution>
            <min_angle>0.000000</min_angle>
            <max_angle>6.280000</max_angle>
          </horizontal>
        </scan>
        <range>
          <min>0.5</min>
          <max>5.0</max>
          <!-- <max>4.5</max> -->
          <!-- <resolution>0.015000</resolution> -->
          <resolution>0.010000</resolution>
        </range>
        <noise>
          <type>gaussian</type>
          <mean>0.0</mean>
          <stddev>0.01</stddev>
        </noise>
      </lidar>
      <topic>scan</topic>
      <gz_frame_id>lidar_link</gz_frame_id>
    </sensor>
  </gazebo>
  <!-- IMU Plugin -->
  <gazebo reference="imu_link">
    <sensor name="imu_sensor" type="imu">
      <always_on>true</always_on>
      <update_rate>100</update_rate>
      <visualize>true</visualize>
      <topic>demo/imu</topic>
      <gz_frame_id>imu_link</gz_frame_id>
      <imu>
        <angular_velocity>
          <x>
            <noise type="gaussian">
              <mean>0.0</mean>
              <stddev>2e-4</stddev>
              <bias_mean>0.0000075</bias_mean>
              <bias_stddev>0.0000008</bias_stddev>
            </noise>
          </x>
          <y>
            <noise type="gaussian">
              <mean>0.0</mean>
              <stddev>2e-4</stddev>
              <bias_mean>0.0000075</bias_mean>
              <bias_stddev>0.0000008</bias_stddev>
            </noise>
          </y>
          <z>
            <noise type="gaussian">
              <mean>0.0</mean>
              <stddev>2e-4</stddev>
              <bias_mean>0.0000075</bias_mean>
              <bias_stddev>0.0000008</bias_stddev>
            </noise>
          </z>
        </angular_velocity>
        <linear_acceleration>
          <x>
            <noise type="gaussian">
              <mean>0.0</mean>
              <stddev>1.7e-2</stddev>
              <bias_mean>0.1</bias_mean>
              <bias_stddev>0.001</bias_stddev>
            </noise>
          </x>
          <y>
            <noise type="gaussian">
              <mean>0.0</mean>
              <stddev>1.7e-2</stddev>
              <bias_mean>0.1</bias_mean>
              <bias_stddev>0.001</bias_stddev>
            </noise>
          </y>
          <z>
            <noise type="gaussian">
              <mean>0.0</mean>
              <stddev>1.7e-2</stddev>
              <bias_mean>0.1</bias_mean>
              <bias_stddev>0.001</bias_stddev>
            </noise>
          </z>
        </linear_acceleration>
      </imu>
    </sensor>
  </gazebo>
  <!-- *************** FRANKA PANDA **************** -->
  <link name="panda_link0">
    <visual>
      <geometry>
        <mesh filename="file:///home/reuben/moveit_ws/install/moveit_resources_panda_description/share/moveit_resources_panda_description/meshes/visual/link0.dae"/>
      </geometry>
    </visual>
    <collision>
      <geometry>
        <mesh filename="file:///home/reuben/moveit_ws/install/moveit_resources_panda_description/share/moveit_resources_panda_description/meshes/collision/link0.stl"/>
      </geometry>
    </collision>
    <inertial>
      <origin rpy="0 0 0" xyz="-0.041018 -0.00014 0.049974"/>
      <mass value="0.629769"/>
      <inertia ixx="0.00315" ixy="8.2904E-7" ixz="0.00015" iyy="0.00388" iyz="8.2299E-6" izz="0.004285"/>
    </inertial>
  </link>
  <link name="panda_link1">
    <visual>
      <geometry>
        <mesh filename="file:///home/reuben/moveit_ws/install/moveit_resources_panda_description/share/moveit_resources_panda_description/meshes/visual/link1.dae"/>
      </geometry>
    </visual>
    <collision>
      <geometry>
        <mesh filename="file:///home/reuben/moveit_ws/install/moveit_resources_panda_description/share/moveit_resources_panda_description/meshes/collision/link1.stl"/>
      </geometry>
    </collision>
    <inertial>
      <origin rpy="0 0 0" xyz="0.003875 0.002081 -0.04762"/>
      <mass value="4.970684"/>
      <inertia ixx="0.70337" ixy="-0.000139" ixz="0.006772" iyy="0.70661" iyz="0.019169" izz="0.009117"/>
    </inertial>
  </link>
  <joint name="panda_joint1" type="revolute">
    <safety_controller k_position="100.0" k_velocity="40.0" soft_lower_limit="-2.8973" soft_upper_limit="2.8973"/>
    <origin rpy="0 0 0" xyz="0 0 0.333"/>
    <parent link="panda_link0"/>
    <child link="panda_link1"/>
    <axis xyz="0 0 1"/>
    <limit effort="87" lower="-2.9671" upper="2.9671" velocity="2.3925"/>
    <dynamics D="1" K="7000" damping="0.003" friction="0.0" mu_coulomb="0" mu_viscous="16"/>
  </joint>
  <link name="panda_link2">
    <visual>
      <geometry>
        <mesh filename="file:///home/reuben/moveit_ws/install/moveit_resources_panda_description/share/moveit_resources_panda_description/meshes/visual/link2.dae"/>
      </geometry>
    </visual>
    <collision>
      <geometry>
        <mesh filename="file:///home/reuben/moveit_ws/install/moveit_resources_panda_description/share/moveit_resources_panda_description/meshes/collision/link2.stl"/>
      </geometry>
    </collision>
    <inertial>
      <origin rpy="0 0 0" xyz="-0.003141 -0.02872  0.003495"/>
      <mass value="0.646926"/>
      <inertia ixx="0.007962" ixy="-3.925E-3" ixz="1.0254E-2" iyy="2.811E-2" iyz="7.04E-4" izz="2.5995E-2"/>
    </inertial>
  </link>
  <joint name="panda_joint2" type="revolute">
    <safety_controller k_position="100.0" k_velocity="40.0" soft_lower_limit="-1.7628" soft_upper_limit="1.7628"/>
    <origin rpy="-1.57079632679 0 0" xyz="0 0 0"/>
    <parent link="panda_link1"/>
    <child link="panda_link2"/>
    <axis xyz="0 0 1"/>
    <limit effort="87" lower="-1.8326" upper="1.8326" velocity="2.3925"/>
    <dynamics D="1" K="7000" damping="0.003" friction="0.0" mu_coulomb="0" mu_viscous="16"/>
  </joint>
  <link name="panda_link3">
    <visual>
      <geometry>
        <mesh filename="file:///home/reuben/moveit_ws/install/moveit_resources_panda_description/share/moveit_resources_panda_description/meshes/visual/link3.dae"/>
      </geometry>
    </visual>
    <collision>
      <geometry>
        <mesh filename="file:///home/reuben/moveit_ws/install/moveit_resources_panda_description/share/moveit_resources_panda_description/meshes/collision/link3.stl"/>
      </geometry>
    </collision>
    <inertial>
      <origin rpy="0 0 0" xyz="2.7518E-2 3.9252E-2 -6.6502E-2"/>
      <mass value="3.228604"/>
      <inertia ixx="3.7242E-2" ixy="-4.761E-3" ixz="-1.1396E-2" iyy="3.6155E-2" iyz="-1.2805E-2" izz="1.083E-2"/>
    </inertial>
  </link>
  <joint name="panda_joint3" type="revolute">
    <safety_controller k_position="100.0" k_velocity="40.0" soft_lower_limit="-2.8973" soft_upper_limit="2.8973"/>
    <origin rpy="1.57079632679 0 0" xyz="0 -0.316 0"/>
    <parent link="panda_link2"/>
    <child link="panda_link3"/>
    <axis xyz="0 0 1"/>
    <limit effort="87" lower="-2.9671" upper="2.9671" velocity="2.3925"/>
    <dynamics D="1" K="7000" damping="0.003" friction="0.0" mu_coulomb="0" mu_viscous="16"/>
  </joint>
  <link name="panda_link4">
    <visual>
      <geometry>
        <mesh filename="file:///home/reuben/moveit_ws/install/moveit_resources_panda_description/share/moveit_resources_panda_description/meshes/visual/link4.dae"/>
      </geometry>
    </visual>
    <collision>
      <geometry>
        <mesh filename="file:///home/reuben/moveit_ws/install/moveit_resources_panda_description/share/moveit_resources_panda_description/meshes/collision/link4.stl"/>
      </geometry>
    </collision>
    <inertial>
      <origin rpy="0 0 0" xyz="-5.317E-2 1.04419E-1 2.7454E-2"/>
      <mass value="3.587895"/>
      <inertia ixx="2.5853E-2" ixy="7.796E-3" ixz="-1.332E-3" iyy="1.9552E-2" iyz="8.641E-3" izz="2.8323E-2"/>
    </inertial>
  </link>
  <joint name="panda_joint4" type="revolute">
    <safety_controller k_position="100.0" k_velocity="40.0" soft_lower_limit="-3.0718" soft_upper_limit="0.0175"/>
    <origin rpy="1.57079632679 0 0" xyz="0.0825 0 0"/>
    <parent link="panda_link3"/>
    <child link="panda_link4"/>
    <axis xyz="0 0 1"/>
    <limit effort="87" lower="-3.1416" upper="0.0873" velocity="2.3925"/>
    <dynamics D="1" K="7000" damping="0.003" friction="0.0" mu_coulomb="0" mu_viscous="16"/>
  </joint>
  <link name="panda_link5">
    <visual>
      <geometry>
        <mesh filename="file:///home/reuben/moveit_ws/install/moveit_resources_panda_description/share/moveit_resources_panda_description/meshes/visual/link5.dae"/>
      </geometry>
    </visual>
    <collision>
      <geometry>
        <mesh filename="file:///home/reuben/moveit_ws/install/moveit_resources_panda_description/share/moveit_resources_panda_description/meshes/collision/link5.stl"/>
      </geometry>
    </collision>
    <inertial>
      <origin rpy="0 0 0" xyz="-1.1953E-2 4.1065E-2 -3.8437E-2"/>
      <mass value="1.225946"/>
      <inertia ixx="3.5549E-2" ixy="-2.117E-3" ixz="-4.037E-3" iyy="2.9474E-2" iyz="2.29E-4" izz="8.627E-3"/>
    </inertial>
  </link>
  <joint name="panda_joint5" type="revolute">
    <safety_controller k_position="100.0" k_velocity="40.0" soft_lower_limit="-2.8973" soft_upper_limit="2.8973"/>
    <origin rpy="-1.57079632679 0 0" xyz="-0.0825 0.384 0"/>
    <parent link="panda_link4"/>
    <child link="panda_link5"/>
    <axis xyz="0 0 1"/>
    <limit effort="12" lower="-2.9671" upper="2.9671" velocity="2.8710"/>
    <dynamics D="1" K="7000" damping="0.003" friction="0.0" mu_coulomb="0" mu_viscous="16"/>
  </joint>
  <link name="panda_link6">
    <visual>
      <geometry>
        <mesh filename="file:///home/reuben/moveit_ws/install/moveit_resources_panda_description/share/moveit_resources_panda_description/meshes/visual/link6.dae"/>
      </geometry>
    </visual>
    <collision>
      <geometry>
        <mesh filename="file:///home/reuben/moveit_ws/install/moveit_resources_panda_description/share/moveit_resources_panda_description/meshes/collision/link6.stl"/>
      </geometry>
    </collision>
    <inertial>
      <origin rpy="0 0 0" xyz="6.0149E-2 -1.4117E-2 -1.0517E-2"/>
      <mass value="1.666555"/>
      <inertia ixx="1.964E-3" ixy="1.09E-4" ixz="-1.158E-3" iyy="4.354E-3" iyz="3.41E-4" izz="5.433E-3"/>
    </inertial>
  </link>
  <joint name="panda_joint6" type="revolute">
    <safety_controller k_position="100.0" k_velocity="40.0" soft_lower_limit="-0.0175" soft_upper_limit="3.7525"/>
    <origin rpy="1.57079632679 0 0" xyz="0 0 0"/>
    <parent link="panda_link5"/>
    <child link="panda_link6"/>
    <axis xyz="0 0 1"/>
    <limit effort="12" lower="-0.0873" upper="3.8223" velocity="2.8710"/>
    <dynamics D="1" K="7000" damping="0.003" friction="0.0" mu_coulomb="0" mu_viscous="16"/>
  </joint>
  <link name="panda_link7">
    <visual>
      <geometry>
        <mesh filename="file:///home/reuben/moveit_ws/install/moveit_resources_panda_description/share/moveit_resources_panda_description/meshes/visual/link7.dae"/>
      </geometry>
    </visual>
    <collision>
      <geometry>
        <mesh filename="file:///home/reuben/moveit_ws/install/moveit_resources_panda_description/share/moveit_resources_panda_description/meshes/collision/link7.stl"/>
      </geometry>
    </collision>
    <inertial>
      <origin rpy="0 0 0" xyz="1.0517E-2 -4.252E-3 6.1597E-2"/>
      <mass value="7.35522E-1"/>
      <inertia ixx="1.2516E-2" ixy="-4.28E-4" ixz="-1.19E-3" iyy="1.0027E-2" iyz="-7.41E-4" izz="4.815E-3"/>
    </inertial>
  </link>
  <joint name="panda_joint7" type="revolute">
    <safety_controller k_position="100.0" k_velocity="40.0" soft_lower_limit="-2.8973" soft_upper_limit="2.8973"/>
    <origin rpy="1.57079632679 0 0" xyz="0.088 0 0"/>
    <parent link="panda_link6"/>
    <child link="panda_link7"/>
    <axis xyz="0 0 1"/>
    <limit effort="12" lower="-2.9671" upper="2.9671" velocity="2.8710"/>
    <dynamics D="1" K="7000" damping="0.003" friction="0.0" mu_coulomb="0" mu_viscous="16"/>
  </joint>
  <link name="panda_link8"/>
  <joint name="panda_joint8" type="fixed">
    <origin rpy="0 0 0" xyz="0 0 0.107"/>
    <parent link="panda_link7"/>
    <child link="panda_link8"/>
    <axis xyz="0 0 0"/>
  </joint>
  <joint name="panda_hand_joint" type="fixed">
    <parent link="panda_link8"/>
    <child link="panda_hand"/>
    <origin rpy="0 0 -0.785398163397" xyz="0 0 0"/>
  </joint>
  <link name="panda_hand">
    <visual>
      <geometry>
        <mesh filename="file:///home/reuben/moveit_ws/install/moveit_resources_panda_description/share/moveit_resources_panda_description/meshes/visual/hand.dae"/>
      </geometry>
    </visual>
    <collision>
      <geometry>
        <mesh filename="file:///home/reuben/moveit_ws/install/moveit_resources_panda_description/share/moveit_resources_panda_description/meshes/collision/hand.stl"/>
      </geometry>
    </collision>
    <inertial>
      <origin rpy="0 0 0" xyz="-0.01 0 0.03"/>
      <mass value="0.73"/>
      <inertia ixx="0.001" ixy="0" ixz="0" iyy="0.0025" iyz="0" izz="0.0017"/>
    </inertial>
  </link>
  <link name="panda_leftfinger">
    <visual>
      <geometry>
        <mesh filename="file:///home/reuben/moveit_ws/install/moveit_resources_panda_description/share/moveit_resources_panda_description/meshes/visual/finger.dae"/>
      </geometry>
    </visual>
    <collision>
      <geometry>
        <mesh filename="file:///home/reuben/moveit_ws/install/moveit_resources_panda_description/share/moveit_resources_panda_description/meshes/collision/finger.stl"/>
      </geometry>
    </collision>
    <inertial>
      <origin rpy="0 0 0" xyz="0 0 0"/>
      <mass value="0.015"/>
      <inertia ixx="2.375E-6" ixy="0" ixz="0" iyy="2.375E-6" iyz="0" izz="7.5E-7"/>
    </inertial>
  </link>
  <link name="panda_rightfinger">
    <visual>
      <origin rpy="0 0 3.14159265359" xyz="0 0 0"/>
      <geometry>
        <mesh filename="file:///home/reuben/moveit_ws/install/moveit_resources_panda_description/share/moveit_resources_panda_description/meshes/visual/finger.dae"/>
      </geometry>
    </visual>
    <collision>
      <origin rpy="0 0 3.14159265359" xyz="0 0 0"/>
      <geometry>
        <mesh filename="file:///home/reuben/moveit_ws/install/moveit_resources_panda_description/share/moveit_resources_panda_description/meshes/collision/finger.stl"/>
      </geometry>
    </collision>
    <inertial>
      <origin rpy="0 0 0" xyz="0 0 0"/>
      <mass value="0.15"/>
      <inertia ixx="2.375E-6" ixy="0" ixz="0" iyy="2.375E-6" iyz="0" izz="7.5E-7"/>
    </inertial>
  </link>
  <joint name="panda_finger_joint1" type="prismatic">
    <parent link="panda_hand"/>
    <child link="panda_leftfinger"/>
    <origin rpy="0 0 0" xyz="0 0 0.0584"/>
    <axis xyz="0 1 0"/>
    <limit effort="20" lower="0.0" upper="0.04" velocity="0.2"/>
    <dynamics damping="0.3"/>
  </joint>
  <joint name="panda_finger_joint2" type="prismatic">
    <parent link="panda_hand"/>
    <child link="panda_rightfinger"/>
    <origin rpy="0 0 0" xyz="0 0 0.0584"/>
    <axis xyz="0 -1 0"/>
    <limit effort="20" lower="0.0" upper="0.04" velocity="0.2"/>
    <mimic joint="panda_finger_joint1"/>
    <dynamics damping="0.3"/>
  </joint>
  <!-- Fixed joint from parent link to panda_link0 -->
  <joint name="panda_on_base_link" type="fixed">
    <parent link="base_link"/>
    <child link="panda_link0"/>
    <origin rpy="0 0 0" xyz="0.0 0 0.09"/>
  </joint>
  <gazebo>
    <plugin filename="gz_ros2_control-system" name="gz_ros2_control::GazeboSimROS2ControlPlugin">
      <!-- <parameters>/home/reuben/moveit_ws/src/sonny_description/config/ros2_controllers.yaml</parameters> -->
      <parameters>/home/reuben/moveit_ws/src/panda_moveit_config/config/ros2_controllers.yaml</parameters>
    </plugin>
  </gazebo>
  <ros2_control name="panda_gz_system" type="system">
    <hardware>
      <plugin>gz_ros2_control/GazeboSimSystem</plugin>
    </hardware>
    <!-- Arm joints -->
    <joint name="panda_joint1">
      <command_interface name="position"/>
      <state_interface name="position"/>
      <state_interface name="velocity"/>
    </joint>
    <joint name="panda_joint2">
      <command_interface name="position"/>
      <state_interface name="position"/>
      <state_interface name="velocity"/>
    </joint>
    <joint name="panda_joint3">
      <command_interface name="position"/>
      <state_interface name="position"/>
      <state_interface name="velocity"/>
    </joint>
    <joint name="panda_joint4">
      <command_interface name="position"/>
      <state_interface name="position">
        <param name="initial_value">-1.57</param>
      </state_interface>
      <state_interface name="velocity"/>
    </joint>
    <joint name="panda_joint5">
      <command_interface name="position"/>
      <state_interface name="position"/>
      <state_interface name="velocity"/>
    </joint>
    <joint name="panda_joint6">
      <command_interface name="position"/>
      <state_interface name="position">
        <param name="initial_value">1.57</param>
      </state_interface>
      <state_interface name="velocity"/>
    </joint>
    <joint name="panda_joint7">
      <command_interface name="position"/>
      <state_interface name="position"/>
      <state_interface name="velocity"/>
    </joint>
    <!-- Optional: gripper joints  -->
    <joint name="panda_finger_joint1">
      <command_interface name="position"/>
      <state_interface name="position">
        <param name="initial_value">0.04</param>
      </state_interface>
      <state_interface name="velocity"/>
    </joint>
    <joint name="panda_finger_joint2">
      <!-- <command_interface name="position"/> -->
      <!-- Caused major issues-->
      <state_interface name="position"/>
      <state_interface name="velocity"/>
    </joint>
  </ros2_control>
  <!-- *************** BOXES **************** -->
  <!-- Green Box -->
  <link name="green_box">
    <visual>
      <geometry>
        <mesh filename="file:///home/reuben/moveit_ws/install/sonny_description/share/sonny_description/meshes/Green_Box.stl" scale="0.001 0.001 0.001"/>
      </geometry>
      <material name="Green">
        <color rgba="0.0 1 0.0 1"/>
      </material>
    </visual>
    <collision>
      <geometry>
        <mesh filename="file:///home/reuben/moveit_ws/install/sonny_description/share/sonny_description/meshes/Green_Box.stl" scale="0.001 0.001 0.001"/>
      </geometry>
    </collision>
    <inertial>
      <origin rpy="1.5707963267948966 0 1.5707963267948966" xyz="0 0 0"/>
      <mass value="5"/>
      <inertia ixx="0.01875" ixy="0.0" ixz="0.0" iyy="0.01875" iyz="0.0" izz="0.01875"/>
    </inertial>
  </link>
  <joint name="green_box_joint" type="fixed">
    <parent link="base_link"/>
    <child link="green_box"/>
    <origin rpy="0 0 0" xyz="-0.195 0.17 0.16499999999999998"/>
  </joint>
  <!-- Red Box -->
  <link name="red_box">
    <visual>
      <geometry>
        <mesh filename="file:///home/reuben/moveit_ws/install/sonny_description/share/sonny_description/meshes/Red_Box.stl" scale="0.001 0.001 0.001"/>
      </geometry>
      <material name="Red">
        <color rgba="1.0 0.0 0.0 1"/>
      </material>
    </visual>
    <collision>
      <geometry>
        <mesh filename="file:///home/reuben/moveit_ws/install/sonny_description/share/sonny_description/meshes/Red_Box.stl" scale="0.001 0.001 0.001"/>
      </geometry>
    </collision>
    <inertial>
      <origin rpy="1.5707963267948966 0 1.5707963267948966" xyz="0 0 0"/>
      <mass value="5"/>
      <inertia ixx="0.01875" ixy="0.0" ixz="0.0" iyy="0.01875" iyz="0.0" izz="0.01875"/>
    </inertial>
  </link>
  <joint name="red_box_joint" type="fixed">
    <parent link="base_link"/>
    <child link="red_box"/>
    <origin rpy="0 0 0" xyz="-0.195 -0.17 0.16499999999999998"/>
  </joint>
</robot>
